<?xml version="1.0" encoding="UTF-8"?>
<!-- Generated by org.testng.reporters.JUnitXMLReporter -->
<testsuite hostname="CE-20150821IBGT" name="test2" tests="5" failures="2" timestamp="17 Apr 2018 09:17:11 GMT" time="23.387" errors="0">
  <testcase name="f" time="0.001" classname="comm.JdongTest"/>
  <testcase name="f" time="0.001" classname="comm.JdongTest"/>
  <testcase name="loanLg" time="2.539" classname="comm.JdongTest">
    <failure type="org.testng.TestException" message="
Method JdongTest.loanLg(java.lang.String, java.lang.String)[pri:0, instance:comm.JdongTest@6b2fad11] should have thrown an exception of type class java.lang.InterruptedException">
      <![CDATA[org.testng.TestException: 
Method JdongTest.loanLg(java.lang.String, java.lang.String)[pri:0, instance:comm.JdongTest@6b2fad11] should have thrown an exception of type class java.lang.InterruptedException
	at org.testng.internal.ExpectedExceptionsHolder.noException(ExpectedExceptionsHolder.java:89)
	at org.testng.internal.Invoker.handleInvocationResults(Invoker.java:1376)
	at org.testng.internal.Invoker.invokeMethod(Invoker.java:677)
	at org.testng.internal.Invoker.invokeTestMethod(Invoker.java:816)
	at org.testng.internal.Invoker.invokeTestMethods(Invoker.java:1124)
	at org.testng.internal.TestMethodWorker.invokeTestMethods(TestMethodWorker.java:125)
	at org.testng.internal.TestMethodWorker.run(TestMethodWorker.java:108)
	at org.testng.TestRunner.privateRun(TestRunner.java:774)
	at org.testng.TestRunner.run(TestRunner.java:624)
	at org.testng.SuiteRunner.runTest(SuiteRunner.java:359)
	at org.testng.SuiteRunner.access$000(SuiteRunner.java:39)
	at org.testng.SuiteRunner$SuiteWorker.run(SuiteRunner.java:393)
	at org.testng.internal.thread.ThreadUtil$2.call(ThreadUtil.java:64)
	at java.util.concurrent.FutureTask.run(Unknown Source)
	at java.util.concurrent.ThreadPoolExecutor.runWorker(Unknown Source)
	at java.util.concurrent.ThreadPoolExecutor$Worker.run(Unknown Source)
	at java.lang.Thread.run(Unknown Source)
]]>
    </failure>
  </testcase> <!-- loanLg -->
  <testcase name="returnurl" time="0.026" classname="comm.JdongTest"/>
  <testcase name="addpro" time="1.69" classname="comm.JdongTest">
    <failure type="java.lang.AssertionError" message="expected [http://10.36.40.211:8383/#/product/FeaturesManage] but found [http://10.36.40.211:8383/#/product/FeaturesAdd]">
      <![CDATA[java.lang.AssertionError: expected [http://10.36.40.211:8383/#/product/FeaturesManage] but found [http://10.36.40.211:8383/#/product/FeaturesAdd]
	at org.testng.Assert.fail(Assert.java:94)
	at org.testng.Assert.failNotEquals(Assert.java:496)
	at org.testng.Assert.assertEquals(Assert.java:125)
	at org.testng.Assert.assertEquals(Assert.java:178)
	at org.testng.Assert.assertEquals(Assert.java:188)
	at comm.JdongTest.addpro(JdongTest.java:127)
	at sun.reflect.NativeMethodAccessorImpl.invoke0(Native Method)
	at sun.reflect.NativeMethodAccessorImpl.invoke(Unknown Source)
	at sun.reflect.DelegatingMethodAccessorImpl.invoke(Unknown Source)
	at java.lang.reflect.Method.invoke(Unknown Source)
	at org.testng.internal.MethodInvocationHelper.invokeMethod(MethodInvocationHelper.java:85)
	at org.testng.internal.Invoker.invokeMethod(Invoker.java:639)
	at org.testng.internal.Invoker.invokeTestMethod(Invoker.java:816)
	at org.testng.internal.Invoker.invokeTestMethods(Invoker.java:1124)
	at org.testng.internal.TestMethodWorker.invokeTestMethods(TestMethodWorker.java:125)
	at org.testng.internal.TestMethodWorker.run(TestMethodWorker.java:108)
	at org.testng.TestRunner.privateRun(TestRunner.java:774)
	at org.testng.TestRunner.run(TestRunner.java:624)
	at org.testng.SuiteRunner.runTest(SuiteRunner.java:359)
	at org.testng.SuiteRunner.access$000(SuiteRunner.java:39)
	at org.testng.SuiteRunner$SuiteWorker.run(SuiteRunner.java:393)
	at org.testng.internal.thread.ThreadUtil$2.call(ThreadUtil.java:64)
	at java.util.concurrent.FutureTask.run(Unknown Source)
	at java.util.concurrent.ThreadPoolExecutor.runWorker(Unknown Source)
	at java.util.concurrent.ThreadPoolExecutor$Worker.run(Unknown Source)
	at java.lang.Thread.run(Unknown Source)
]]>
    </failure>
  </testcase> <!-- addpro -->
</testsuite> <!-- test2 -->
